2022-04-27 14:48:13,363 INFO    MainThread:8093 [internal.py:wandb_internal():90] W&B internal server running at pid: 8093, started at: 2022-04-27 14:48:13.363666
2022-04-27 14:48:13,364 DEBUG   HandlerThread:8093 [handler.py:handle_request():141] handle_request: check_version
2022-04-27 14:48:13,364 INFO    WriterThread:8093 [datastore.py:open_for_write():75] open: /Users/gmmyung/Developer/RoboVision/wandb/run-20220427_144806-rrzccxxc/run-rrzccxxc.wandb
2022-04-27 14:48:13,365 DEBUG   SenderThread:8093 [sender.py:send():232] send: header
2022-04-27 14:48:13,365 DEBUG   SenderThread:8093 [sender.py:send_request():246] send_request: check_version
2022-04-27 14:48:13,433 DEBUG   SenderThread:8093 [sender.py:send():232] send: run
2022-04-27 14:48:43,441 DEBUG   HandlerThread:8093 [handler.py:handle_request():141] handle_request: shutdown
2022-04-27 14:48:43,442 INFO    HandlerThread:8093 [handler.py:finish():806] shutting down handler
2022-04-27 14:48:43,560 INFO    WriterThread:8093 [datastore.py:close():279] close: /Users/gmmyung/Developer/RoboVision/wandb/run-20220427_144806-rrzccxxc/run-rrzccxxc.wandb
2022-04-27 14:48:47,197 ERROR   SenderThread:8093 [retry.py:__call__():126] Retry attempt failed:
Traceback (most recent call last):
  File "/Users/gmmyung/miniconda3/envs/gazetrack/lib/python3.8/site-packages/urllib3/connectionpool.py", line 449, in _make_request
    six.raise_from(e, None)
  File "<string>", line 3, in raise_from
  File "/Users/gmmyung/miniconda3/envs/gazetrack/lib/python3.8/site-packages/urllib3/connectionpool.py", line 444, in _make_request
    httplib_response = conn.getresponse()
  File "/Users/gmmyung/miniconda3/envs/gazetrack/lib/python3.8/http/client.py", line 1344, in getresponse
    response.begin()
  File "/Users/gmmyung/miniconda3/envs/gazetrack/lib/python3.8/http/client.py", line 307, in begin
    version, status, reason = self._read_status()
  File "/Users/gmmyung/miniconda3/envs/gazetrack/lib/python3.8/http/client.py", line 268, in _read_status
    line = str(self.fp.readline(_MAXLINE + 1), "iso-8859-1")
  File "/Users/gmmyung/miniconda3/envs/gazetrack/lib/python3.8/socket.py", line 669, in readinto
    return self._sock.recv_into(b)
  File "/Users/gmmyung/miniconda3/envs/gazetrack/lib/python3.8/ssl.py", line 1241, in recv_into
    return self.read(nbytes, buffer)
  File "/Users/gmmyung/miniconda3/envs/gazetrack/lib/python3.8/ssl.py", line 1099, in read
    return self._sslobj.read(len, buffer)
socket.timeout: The read operation timed out

During handling of the above exception, another exception occurred:

Traceback (most recent call last):
  File "/Users/gmmyung/miniconda3/envs/gazetrack/lib/python3.8/site-packages/requests/adapters.py", line 440, in send
    resp = conn.urlopen(
  File "/Users/gmmyung/miniconda3/envs/gazetrack/lib/python3.8/site-packages/urllib3/connectionpool.py", line 785, in urlopen
    retries = retries.increment(
  File "/Users/gmmyung/miniconda3/envs/gazetrack/lib/python3.8/site-packages/urllib3/util/retry.py", line 550, in increment
    raise six.reraise(type(error), error, _stacktrace)
  File "/Users/gmmyung/miniconda3/envs/gazetrack/lib/python3.8/site-packages/urllib3/packages/six.py", line 770, in reraise
    raise value
  File "/Users/gmmyung/miniconda3/envs/gazetrack/lib/python3.8/site-packages/urllib3/connectionpool.py", line 703, in urlopen
    httplib_response = self._make_request(
  File "/Users/gmmyung/miniconda3/envs/gazetrack/lib/python3.8/site-packages/urllib3/connectionpool.py", line 451, in _make_request
    self._raise_timeout(err=e, url=url, timeout_value=read_timeout)
  File "/Users/gmmyung/miniconda3/envs/gazetrack/lib/python3.8/site-packages/urllib3/connectionpool.py", line 340, in _raise_timeout
    raise ReadTimeoutError(
urllib3.exceptions.ReadTimeoutError: HTTPSConnectionPool(host='api.wandb.ai', port=443): Read timed out. (read timeout=10)

During handling of the above exception, another exception occurred:

Traceback (most recent call last):
  File "/Users/gmmyung/miniconda3/envs/gazetrack/lib/python3.8/site-packages/wandb/sdk/lib/retry.py", line 102, in __call__
    result = self._call_fn(*args, **kwargs)
  File "/Users/gmmyung/miniconda3/envs/gazetrack/lib/python3.8/site-packages/wandb/sdk/internal/internal_api.py", line 140, in execute
    return self.client.execute(*args, **kwargs)
  File "/Users/gmmyung/miniconda3/envs/gazetrack/lib/python3.8/site-packages/wandb/vendor/gql-0.2.0/wandb_gql/client.py", line 52, in execute
    result = self._get_result(document, *args, **kwargs)
  File "/Users/gmmyung/miniconda3/envs/gazetrack/lib/python3.8/site-packages/wandb/vendor/gql-0.2.0/wandb_gql/client.py", line 60, in _get_result
    return self.transport.execute(document, *args, **kwargs)
  File "/Users/gmmyung/miniconda3/envs/gazetrack/lib/python3.8/site-packages/wandb/vendor/gql-0.2.0/wandb_gql/transport/requests.py", line 38, in execute
    request = requests.post(self.url, **post_args)
  File "/Users/gmmyung/miniconda3/envs/gazetrack/lib/python3.8/site-packages/requests/api.py", line 117, in post
    return request('post', url, data=data, json=json, **kwargs)
  File "/Users/gmmyung/miniconda3/envs/gazetrack/lib/python3.8/site-packages/requests/api.py", line 61, in request
    return session.request(method=method, url=url, **kwargs)
  File "/Users/gmmyung/miniconda3/envs/gazetrack/lib/python3.8/site-packages/requests/sessions.py", line 529, in request
    resp = self.send(prep, **send_kwargs)
  File "/Users/gmmyung/miniconda3/envs/gazetrack/lib/python3.8/site-packages/requests/sessions.py", line 645, in send
    r = adapter.send(request, **kwargs)
  File "/Users/gmmyung/miniconda3/envs/gazetrack/lib/python3.8/site-packages/requests/adapters.py", line 532, in send
    raise ReadTimeout(e, request=request)
requests.exceptions.ReadTimeout: HTTPSConnectionPool(host='api.wandb.ai', port=443): Read timed out. (read timeout=10)
2022-04-27 14:49:41,099 INFO    SenderThread:8093 [dir_watcher.py:__init__():166] watching files in: /Users/gmmyung/Developer/RoboVision/wandb/run-20220427_144806-rrzccxxc/files
2022-04-27 14:49:41,100 INFO    SenderThread:8093 [sender.py:_start_run_threads():811] run started: rrzccxxc with start time 1651038492
2022-04-27 14:49:41,100 INFO    SenderThread:8093 [sender.py:finish():1106] shutting down sender
2022-04-27 14:49:41,101 INFO    SenderThread:8093 [dir_watcher.py:finish():279] shutting down directory watcher
2022-04-27 14:49:42,104 INFO    SenderThread:8093 [dir_watcher.py:finish():309] scan: /Users/gmmyung/Developer/RoboVision/wandb/run-20220427_144806-rrzccxxc/files
2022-04-27 14:49:42,104 INFO    SenderThread:8093 [dir_watcher.py:finish():323] scan save: /Users/gmmyung/Developer/RoboVision/wandb/run-20220427_144806-rrzccxxc/files/config.yaml config.yaml
2022-04-27 14:49:42,105 INFO    SenderThread:8093 [file_pusher.py:finish():145] shutting down file pusher
2022-04-27 14:49:42,105 INFO    SenderThread:8093 [file_pusher.py:join():150] waiting for file pusher
2022-04-27 14:49:43,325 INFO    Thread-10 :8093 [upload_job.py:push():137] Uploaded file /Users/gmmyung/Developer/RoboVision/wandb/run-20220427_144806-rrzccxxc/files/config.yaml
2022-04-27 14:49:43,959 INFO    MainThread:8093 [internal.py:handle_exit():80] Internal process exited
